try{
    console.log("Teste")
    let b
    console.log(b + c)
}
catch(err){
    console.log(err)
}

